# 异常

## 异常入门

```java
public class Main {
    final static long mod = (int)(1e9 + 7);

    public static long feibo(long n) throws Exception {
        if (n < 0) throw new Exception("索引负数");
        if (n > 1e8) throw new Exception("O(n) 时间复杂度超时");
        long a = 1, b = 1;
        if (n <= 1) return 1;
        for (long i = 2; i <= n; i ++) {
            a += b;
            var t = a % mod;
            a = b;
            b = t;
        }
        return b;
    }

    public static void main(String[] args) {
        System.out.println("Hello world!");
    }
}
```

使用关键字 `throw` 抛出异常，如果当前函数需要抛出异常给上级处理，就需要在函数声明后使用 `throws Exception` 修饰，指明该函数需要抛出异常

使用 `throw` 抛出一个异常实例，实例里面存放异常信息，`throw Exception(String message)`

捕获异常：

```java
try {}
catch(Exception1 e1) {}
catch(Exception2 e2) {}
catch(Exception3 e3) {}
finally {}
```

假设 try 语句块中抛出了异常 e，结果 e 是 Exception1 和 Exception2 的后代，导致 e 的可匹配的错误类型有两种，java 是不允许的

```java
try {}
catch(Exception1 | Exception2 e) {}
finally {}
```

try 语句块抛出的异常类型匹配上 `Exception1` 类型或者是 `Exception2` 类型中的一个就执行 catch 语句块

```java
import java.io.*;
import java.nio.Buffer;

public class Main {
    public static void main(String[] args) {
        var in = new BufferedReader(new InputStreamReader(System.in));
        var out = new PrintWriter(new OutputStreamWriter(System.out));
        try {
            var s = in.readLine();
        } catch (Exception | IOException e) {
  
        }
    }
}
```

上方代码错误，因为抛出的异常实例可同时匹配上 `Exception` 和 `IOException` 类型

`finally` 语句，无论是否发生异常，编译器都 **一定** 会执行的，要深刻理解 **一定** 的含金量：

```java
public class Main {
    public static String test() {
        try {                   // 抛出异常
            throw new Exception("finally 语句是一定会执行的");
        }
        catch (Exception e) {   // 捕获异常
            return "catch 语句执行";
        }
        finally {
            return "finally 语句无论如何都会执行，导致 catch 语句块的 return 语句被覆盖掉";
        }
    }
    public static void main(String[] args) {
        System.out.println(test());
    }
}
```

输出：

```java
finally 语句无论如何都会执行，导致 catch 语句块的 return 语句被覆盖掉
```

不仅 catch 的返回值会被覆盖掉，就连 catch 语句块抛出的异常也会被 finally 覆盖掉：

```java
public class Main {
    public static void test() throws Exception {
        try {                   // 抛出异常
            throw new Exception("finally 语句是一定会执行的");
        }
        catch (Exception e) {   // 捕获异常
            throw new Exception("catch 语句块抛出异常");
        }
        finally {
            throw new Exception("finally 语句块无论如何都会执行，并且还会覆盖掉 catch 语句块抛出的异常");
        }
    }
    public static void main(String[] args) {
        try {
            test();
        }
        catch (Exception e) {
            System.out.println(e.getMessage());
        }
    }
}
```

输出：

```java
finally 语句块无论如何都会执行，并且还会覆盖掉 catch 语句块抛出的异常
```

## 自定义异常

继承类 `Exception`，自定义的异常应该提供多种构造方法：

```java
class ValueException extends Exception {
    ValueException() { super(); }
    ValueException(String message) { super(message); }
    ValueException(String message, Throwable cause) { super(message, cause); }
    ValueException(Throwable cause) { super(cause); }
}
```
